<?xml version="1.0" encoding="utf-8"?>
<!-- This URDF was automatically created by SolidWorks to URDF Exporter! Originally created by Stephen Brawner (brawner@gmail.com) 
     Commit Version: 1.5.1-0-g916b5db  Build Version: 1.5.7152.31018
     For more information, please see http://wiki.ros.org/sw_urdf_exporter -->
<robot
  name="pick_ball_mbot">
  <link
    name="base_link">
    <inertial>
      <origin
        xyz="0.012976 -0.013657 0.17563"
        rpy="0 0 0" />
      <mass
        value="1.0824" />
      <inertia
        ixx="0.0036507"
        ixy="8.5713E-20"
        ixz="-2.2831E-19"
        iyy="0.0038702"
        iyz="-0.00014855"
        izz="0.0015847" />
    </inertial>
    <visual>
      <origin
        xyz="0 0 0"
        rpy="0 0 0" />
      <geometry>
        <mesh
          filename="package://pick_ball_mbot/meshes/base_link.STL" />
      </geometry>
      <material
        name="">
        <color
          rgba="0.79216 0.81961 0.93333 1" />
      </material>
    </visual>
    <collision>
      <origin
        xyz="0 0 0"
        rpy="0 0 0" />
      <geometry>
        <mesh
          filename="package://pick_ball_mbot/meshes/base_link.STL" />
      </geometry>
    </collision>
  </link>
  <link
    name="front_right_wheel">
    <inertial>
      <origin
        xyz="3.21062620933787E-12 -1.27994836951473E-13 0.014176412344854"
        rpy="0 0 0" />
      <mass
        value="0.0937829390237727" />
      <inertia
        ixx="3.09771819038864E-05"
        ixy="1.13085557310682E-09"
        ixz="6.33875303444406E-15"
        iyy="3.10054948109752E-05"
        iyz="-2.52783953359037E-16"
        izz="4.77838078287252E-05" />
    </inertial>
    <visual>
      <origin
        xyz="0 0 0"
        rpy="0 0 0" />
      <geometry>
        <mesh
          filename="package://pick_ball_mbot/meshes/front_right_wheel.STL" />
      </geometry>
      <material
        name="">
        <color
          rgba="1 1 1 1" />
      </material>
    </visual>
    <collision>
      <origin
        xyz="0 0 0"
        rpy="0 0 0" />
      <geometry>
        <mesh
          filename="package://pick_ball_mbot/meshes/front_right_wheel.STL" />
      </geometry>
    </collision>
  </link>
  <joint
    name="front_right_wheel_joint"
    type="continuous">
    <origin
      xyz="-0.066074 -0.10152 -0.030048"
      rpy="1.5708 1.5309 -1.5744" />
    <parent
      link="base_link" />
    <child
      link="front_right_wheel" />
    <axis
      xyz="0 0 0" />
  </joint>
  <link
    name="front_left_wheel">
    <inertial>
      <origin
        xyz="7.36868899231524E-13 -3.12904910315659E-12 0.0148235876550204"
        rpy="0 0 0" />
      <mass
        value="0.0937829390237727" />
      <inertia
        ixx="3.10038750554585E-05"
        ixy="6.67197191832215E-09"
        ixz="-1.50548030860998E-15"
        iyy="3.09788016590389E-05"
        iyz="6.16076592224176E-15"
        izz="4.77838078287253E-05" />
    </inertial>
    <visual>
      <origin
        xyz="0 0 0"
        rpy="0 0 0" />
      <geometry>
        <mesh
          filename="package://pick_ball_mbot/meshes/front_left_wheel.STL" />
      </geometry>
      <material
        name="">
        <color
          rgba="1 1 1 1" />
      </material>
    </visual>
    <collision>
      <origin
        xyz="0 0 0"
        rpy="0 0 0" />
      <geometry>
        <mesh
          filename="package://pick_ball_mbot/meshes/front_left_wheel.STL" />
      </geometry>
    </collision>
  </link>
  <joint
    name="front_left_wheel_joint"
    type="continuous">
    <origin
      xyz="0.12101 -0.10059 -0.030048"
      rpy="1.5708 0.24454 -1.546" />
    <parent
      link="base_link" />
    <child
      link="front_left_wheel" />
    <axis
      xyz="0 0 0" />
  </joint>
  <link
    name="rear_left_wheel">
    <inertial>
      <origin
        xyz="-2.77555756156289E-17 3.21316931395366E-12 -0.0141764123448539"
        rpy="0 0 0" />
      <mass
        value="0.0937829390237727" />
      <inertia
        ixx="3.10055399070393E-05"
        ixy="3.90518914781106E-24"
        ixz="5.92948462490062E-20"
        iyy="3.09771368078223E-05"
        iyz="-6.344397796191E-15"
        izz="4.77838078287253E-05" />
    </inertial>
    <visual>
      <origin
        xyz="0 0 0"
        rpy="0 0 0" />
      <geometry>
        <mesh
          filename="package://pick_ball_mbot/meshes/rear_left_wheel.STL" />
      </geometry>
      <material
        name="">
        <color
          rgba="1 1 1 1" />
      </material>
    </visual>
    <collision>
      <origin
        xyz="0 0 0"
        rpy="0 0 0" />
      <geometry>
        <mesh
          filename="package://pick_ball_mbot/meshes/rear_left_wheel.STL" />
      </geometry>
    </collision>
  </link>
  <joint
    name="rear_left_wheel_joint"
    type="continuous">
    <origin
      xyz="0.092074 -0.24356 -0.030048"
      rpy="1.5708 0 -1.5708" />
    <parent
      link="base_link" />
    <child
      link="rear_left_wheel" />
    <axis
      xyz="0 0 0" />
  </joint>
  <link
    name="rear_right_wheel">
    <inertial>
      <origin
        xyz="3.13210568592126E-12 7.17287340634698E-13 0.0148235876551461"
        rpy="0 0 0" />
      <mass
        value="0.0937829390237727" />
      <inertia
        ixx="3.09785521091164E-05"
        ixy="-6.18028035977606E-09"
        ixz="-6.18403139274761E-15"
        iyy="3.10041246057451E-05"
        iyz="-1.41616086299302E-15"
        izz="4.77838078287253E-05" />
    </inertial>
    <visual>
      <origin
        xyz="0 0 0"
        rpy="0 0 0" />
      <geometry>
        <mesh
          filename="package://pick_ball_mbot/meshes/rear_right_wheel.STL" />
      </geometry>
      <material
        name="">
        <color
          rgba="1 1 1 1" />
      </material>
    </visual>
    <collision>
      <origin
        xyz="0 0 0"
        rpy="0 0 0" />
      <geometry>
        <mesh
          filename="package://pick_ball_mbot/meshes/rear_right_wheel.STL" />
      </geometry>
    </collision>
  </link>
  <joint
    name="rear_right_wheel_joint"
    type="continuous">
    <origin
      xyz="-0.095123 -0.24365 -0.030048"
      rpy="-1.5708 1.3457 -1.5685" />
    <parent
      link="base_link" />
    <child
      link="rear_right_wheel" />
    <axis
      xyz="0 0 0" />
  </joint>
  <link
    name="collector">
    <inertial>
      <origin
        xyz="0.00290907494232911 -0.040890215457459 0.173468819063094"
        rpy="0 0 0" />
      <mass
        value="0.373810739586063" />
      <inertia
        ixx="0.00346608745603927"
        ixy="9.69850646937143E-06"
        ixz="-2.84961455748493E-05"
        iyy="0.00429300102178934"
        iyz="0.000599276181565496"
        izz="0.00198702343757656" />
    </inertial>
    <visual>
      <origin
        xyz="0 0 0"
        rpy="0 0 0" />
      <geometry>
        <mesh
          filename="package://pick_ball_mbot/meshes/collector.STL" />
      </geometry>
      <material
        name="">
        <color
          rgba="0.792156862745098 0.819607843137255 0.933333333333333 1" />
      </material>
    </visual>
    <collision>
      <origin
        xyz="0 0 0"
        rpy="0 0 0" />
      <geometry>
        <mesh
          filename="package://pick_ball_mbot/meshes/collector.STL" />
      </geometry>
    </collision>
  </link>
  <joint
    name="collector_joint"
    type="fixed">
    <origin
      xyz="0.0094753 -0.11331 0.048119"
      rpy="1.5708 0 0" />
    <parent
      link="base_link" />
    <child
      link="collector" />
    <axis
      xyz="0 0 0" />
  </joint>
  <link
    name="left_cover">
    <inertial>
      <origin
        xyz="0.0339621470957824 0.172876722995866 0.102900925287308"
        rpy="0 0 0" />
      <mass
        value="0.348968668389245" />
      <inertia
        ixx="0.00220864016851107"
        ixy="-9.94750925634307E-05"
        ixz="-0.000119883170893584"
        iyy="0.00198390619746038"
        iyz="-0.00035732246789374"
        izz="0.000935622364147671" />
    </inertial>
    <visual>
      <origin
        xyz="0 0 0"
        rpy="0 0 0" />
      <geometry>
        <mesh
          filename="package://pick_ball_mbot/meshes/left_cover.STL" />
      </geometry>
      <material
        name="">
        <color
          rgba="1 1 1 1" />
      </material>
    </visual>
    <collision>
      <origin
        xyz="0 0 0"
        rpy="0 0 0" />
      <geometry>
        <mesh
          filename="package://pick_ball_mbot/meshes/left_cover.STL" />
      </geometry>
    </collision>
  </link>
  <joint
    name="left_cover_joint"
    type="fixed">
    <origin
      xyz="0.01014 -0.11017 0.072246"
      rpy="-1.5708 0 0" />
    <parent
      link="collector" />
    <child
      link="left_cover" />
    <axis
      xyz="0 0 0" />
  </joint>
  <link
    name="right_cover">
    <inertial>
      <origin
        xyz="-0.00573994781975205 -0.0426051719539319 0.00250436597775372"
        rpy="0 0 0" />
      <mass
        value="0.109962415450793" />
      <inertia
        ixx="0.00015179667895952"
        ixy="-5.32196527116854E-05"
        ixz="-3.8888262975532E-09"
        iyy="0.000384457111161325"
        iyz="4.02644466212908E-08"
        izz="0.000535795937644261" />
    </inertial>
    <visual>
      <origin
        xyz="0 0 0"
        rpy="0 0 0" />
      <geometry>
        <mesh
          filename="package://pick_ball_mbot/meshes/right_cover.STL" />
      </geometry>
      <material
        name="">
        <color
          rgba="1 1 1 1" />
      </material>
    </visual>
    <collision>
      <origin
        xyz="0 0 0"
        rpy="0 0 0" />
      <geometry>
        <mesh
          filename="package://pick_ball_mbot/meshes/right_cover.STL" />
      </geometry>
    </collision>
  </link>
  <joint
    name="right_cover_joint"
    type="fixed">
    <origin
      xyz="-0.055 0.0098333 -0.15183"
      rpy="-1.5708 0 1.5708" />
    <parent
      link="collector" />
    <child
      link="right_cover" />
    <axis
      xyz="0 0 0" />
  </joint>
  <link
    name="right_support_rod">
    <inertial>
      <origin
        xyz="-0.0013764782936087 0.038550080437723 0"
        rpy="0 0 0" />
      <mass
        value="0.00511240249562874" />
      <inertia
        ixx="4.56403013951185E-06"
        ixy="-2.5136215429555E-07"
        ixz="-1.05770456001034E-18"
        iyy="1.1174576332198E-07"
        iyz="-2.28998634241562E-22"
        izz="4.55443005887314E-06" />
    </inertial>
    <visual>
      <origin
        xyz="0 0 0"
        rpy="0 0 0" />
      <geometry>
        <mesh
          filename="package://pick_ball_mbot/meshes/right_support_rod.STL" />
      </geometry>
      <material
        name="">
        <color
          rgba="0.792156862745098 0.819607843137255 0.933333333333333 1" />
      </material>
    </visual>
    <collision>
      <origin
        xyz="0 0 0"
        rpy="0 0 0" />
      <geometry>
        <mesh
          filename="package://pick_ball_mbot/meshes/right_support_rod.STL" />
      </geometry>
    </collision>
  </link>
  <joint
    name="right_support_rod_joint"
    type="fixed">
    <origin
      xyz="-0.018957 -0.11344 -0.047048"
      rpy="1.5708 0 0" />
    <parent
      link="base_link" />
    <child
      link="right_support_rod" />
    <axis
      xyz="0 0 0" />
  </joint>
  <link
    name="left_support_rod">
    <inertial>
      <origin
        xyz="-0.0013764782936211 0.0385500804377229 1.38777878078145E-17"
        rpy="0 0 0" />
      <mass
        value="0.00511240249562874" />
      <inertia
        ixx="4.56403013951185E-06"
        ixy="-2.51362154297282E-07"
        ixz="-1.10898032490382E-18"
        iyy="1.11745728122124E-07"
        iyz="1.86614419528822E-21"
        izz="4.55443002367328E-06" />
    </inertial>
    <visual>
      <origin
        xyz="0 0 0"
        rpy="0 0 0" />
      <geometry>
        <mesh
          filename="package://pick_ball_mbot/meshes/left_support_rod.STL" />
      </geometry>
      <material
        name="">
        <color
          rgba="0.792156862745098 0.819607843137255 0.933333333333333 1" />
      </material>
    </visual>
    <collision>
      <origin
        xyz="0 0 0"
        rpy="0 0 0" />
      <geometry>
        <mesh
          filename="package://pick_ball_mbot/meshes/left_support_rod.STL" />
      </geometry>
    </collision>
  </link>
  <joint
    name="left_support_rod_joint"
    type="fixed">
    <origin
      xyz="0.044933 -0.11344 -0.047048"
      rpy="1.5708 0 3.1416" />
    <parent
      link="base_link" />
    <child
      link="left_support_rod" />
    <axis
      xyz="0 0 0" />
  </joint>
  <link
    name="paddle">
    <inertial>
      <origin
        xyz="0 0 0"
        rpy="0 0 0" />
      <mass
        value="0" />
      <inertia
        ixx="0"
        ixy="0"
        ixz="0"
        iyy="0"
        iyz="0"
        izz="0" />
    </inertial>
    <visual>
      <origin
        xyz="0 0 0"
        rpy="0 0 0" />
      <geometry>
        <mesh
          filename="package://pick_ball_mbot/meshes/paddle.STL" />
      </geometry>
      <material
        name="">
        <color
          rgba="1 1 1 1" />
      </material>
    </visual>
    <collision>
      <origin
        xyz="0 0 0"
        rpy="0 0 0" />
      <geometry>
        <mesh
          filename="package://pick_ball_mbot/meshes/paddle.STL" />
      </geometry>
    </collision>
  </link>
  <joint
    name="paddle_joint"
    type="continuous">
    <origin
      xyz="0 0.038521 0.057952"
      rpy="2.6432 0 -3.1416" />
    <parent
      link="base_link" />
    <child
      link="paddle" />
    <axis
      xyz="1 0 0" />
  </joint>
</robot>