<?xml version="1.0"?>
<robot name="pick_ball_mbot" xmlns:xacro="http://www.ros.org/wiki/xacro">

    <xacro:include filename="$(find pick_ball_mbot_description)/urdf/pick_ball_mbot_base.xacro" />
    <xacro:include filename="$(find pick_ball_mbot_description)/urdf/sensors/kinect_gazebo.xacro" />
    <xacro:include filename="$(find pick_ball_mbot_description)/urdf/sensors/lidar_gazebo.xacro" />
    <xacro:include filename="$(find pick_ball_mbot_description)/urdf/joint_transmission_gazebo.xacro" />
    <xacro:include filename="$(find pick_ball_mbot_description)/urdf/paddle_gazebo.xacro" />
    <xacro:include filename="$(find pick_ball_mbot_description)/urdf/extend_board.xacro" />
    <xacro:include filename="$(find pick_ball_mbot_description)/urdf/top_stage_gazebo.xacro" />


    <xacro:property name="wheel_mu1" value="10"/>
    <xacro:property name="wheel_mu2" value="50"/>

    <!-- extend board -->
    <joint name="extend_board_joint" type="fixed">
        <origin xyz="-0.0050 0.295 0.238" rpy="0 0 1.5707" />
        <parent link="left_cover"/>
        <child link="extend_board"/>
    </joint>
    <extend_board/>

    <!-- kinect -->
    <joint name="kinect_joint" type="fixed">
        <origin xyz="0.05 0 0.01" rpy="0 0.55 0" />
        <parent link="extend_board"/>
        <child link="kinect_link"/>
    </joint>
    <xacro:kinect_camera prefix="kinect"/>

    <!-- top_stage -->
    <joint name="top_stage_joint" type="fixed">
        <origin xyz="0.015 0 0.015" rpy="0 0 0" />
        <parent link="extend_board"/>
        <child link="top_stage_link"/>
    </joint>

    <xacro:top_stage_link />

    <!-- lidar -->
    <joint name="lidar_joint" type="fixed">
        <origin xyz="0 0 0.02" rpy="0 0 0" />
        <parent link="top_stage_link"/>
        <child link="laser_link"/>
    </joint>
    <xacro:rplidar prefix="laser"/>


    <!-- paddle -->
    <joint name="paddle_joint" type="continuous">
        <origin xyz="0 0.22408 0.12" rpy="0.94075 0 3.1416" />
        <parent link="left_cover" />
        <child link="paddle" />
        <axis xyz="1 0 0" />
    </joint>
    <paddle_gazebo/>

    <pick_ball_mbot_base_gazebo/>
    
    <!--- design color for mbot -->
    <gazebo reference="left_cover">
        <material>Gazebo/Red</material>
    </gazebo>
    <gazebo reference="right_cover">
        <material>Gazebo/Red</material>
    </gazebo>
    <gazebo reference="base_link">
        <material>Gazebo/Blue</material>
    </gazebo>
    <gazebo reference="front_right_wheel">
        <material>Gazebo/Black</material>
    </gazebo>
    <gazebo reference="front_left_wheel">
        <material>Gazebo/Black</material>
    </gazebo>
    <gazebo reference="rear_right_wheel">
        <material>Gazebo/Black</material>
    </gazebo>
    <gazebo reference="rear_left_wheel">
        <material>Gazebo/Black</material>
    </gazebo>
    <gazebo reference="collector">
        <material>Gazebo/Wood</material>
    </gazebo>
    <gazebo reference="paddle">
        <material>Gazebo/Black</material>
    </gazebo>
    <gazebo reference="support_rod">
        <material>Gazebo/Purple</material>
    </gazebo>

    <!-- friction -->
    <!--<gazebo reference="front_left_wheel">
        <mu1>${wheel_mu1}</mu1>
        <mu2>${wheel_mu2}</mu2>
    </gazebo>

    <gazebo reference="front_right_wheel">
        <mu1>${wheel_mu1}</mu1>
        <mu2>${wheel_mu2}</mu2>
    </gazebo>

    <gazebo reference="rear_left_wheel">
        <mu1>${wheel_mu1}</mu1>
        <mu2>${wheel_mu2}</mu2>
    </gazebo>

    <gazebo reference="rear_right_wheel">
        <mu1>${wheel_mu1}</mu1>
        <mu2>${wheel_mu2}</mu2>
    </gazebo>-->

    <!-- design transmission for joint-->
    <!--<joint_trans joint_name="front_right_wheel_joint"/>
    <joint_trans joint_name="front_left_wheel_joint"/>
    <joint_trans joint_name="rear_right_wheel_joint"/>
    <joint_trans joint_name="rear_left_wheel_joint"/>-->
    <joint_trans joint_name="paddle_joint"/>


    <gazebo>
        <plugin name="skid_steer_drive_controller" filename="libgazebo_ros_skid_steer_drive.so">
            <updateRate>50.0</updateRate>
            <robotNamespace>/</robotNamespace>
            <leftFrontJoint>front_left_wheel_joint</leftFrontJoint>
            <leftRearJoint>rear_left_wheel_joint</leftRearJoint>
            <rightFrontJoint>front_right_wheel_joint</rightFrontJoint>
            <rightRearJoint>rear_right_wheel_joint</rightRearJoint>
            <wheelSeparation>0.12</wheelSeparation>
            <wheelDiameter>0.064</wheelDiameter>
            <commandTopic>/cmd_vel</commandTopic>
            <odometryTopic>odom</odometryTopic>
            <robotBaseFrame>base_footprint</robotBaseFrame>
            <odometryFrame>odom</odometryFrame>
            <torque>1</torque>
            <topicName>/cmd_vel</topicName>
            <broadcastTF>1</broadcastTF>
        </plugin>
    </gazebo>

</robot>
