<?xml version="1.0" encoding="utf-8"?>
<!-- This URDF was automatically created by SolidWorks to URDF Exporter! Originally created by Stephen Brawner (brawner@gmail.com) 
     Commit Version: 1.5.1-0-g916b5db  Build Version: 1.5.7152.31018
     For more information, please see http://wiki.ros.org/sw_urdf_exporter -->
<robot
  name="pick_ball_mbot">
  <link
    name="base_link">
    <inertial>
      <origin
        xyz="0.0635 -0.099933 0.048391"
        rpy="0 0 0" />
      <mass
        value="1.0824" />
      <inertia
        ixx="0.0036507"
        ixy="4.1119E-19"
        ixz="-1.6118E-19"
        iyy="0.0015847"
        iyz="-0.00014855"
        izz="0.0038702" />
    </inertial>
    <visual>
      <origin
        xyz="0 0 0"
        rpy="0 0 0" />
      <geometry>
        <mesh
          filename="package://pick_ball_mbot/meshes/base_link.STL" />
      </geometry>
      <material
        name="">
        <color
          rgba="0.68627 0 0 1" />
      </material>
    </visual>
    <collision>
      <origin
        xyz="0 0 0"
        rpy="0 0 0" />
      <geometry>
        <mesh
          filename="package://pick_ball_mbot/meshes/base_link.STL" />
      </geometry>
    </collision>
  </link>
  <link
    name="front_left_wheel">
    <inertial>
      <origin
        xyz="2.294E-12 5.7715E-13 0.014824"
        rpy="0 0 0" />
      <mass
        value="0.093783" />
      <inertia
        ixx="3.0979E-05"
        ixy="-6.7569E-09"
        ixz="-6.6396E-15"
        iyy="3.1004E-05"
        iyz="-1.6704E-15"
        izz="4.7784E-05" />
    </inertial>
    <visual>
      <origin
        xyz="0 0 0"
        rpy="0 0 0" />
      <geometry>
        <mesh
          filename="package://pick_ball_mbot/meshes/front_left_wheel.STL" />
      </geometry>
      <material
        name="">
        <color
          rgba="1 1 1 1" />
      </material>
    </visual>
    <collision>
      <origin
        xyz="0 0 0"
        rpy="0 0 0" />
      <geometry>
        <mesh
          filename="package://pick_ball_mbot/meshes/front_left_wheel.STL" />
      </geometry>
    </collision>
  </link>
  <joint
    name="front_left_wheel_joint"
    type="continuous">
    <origin
      xyz="-0.044546 -0.17456 0.032"
      rpy="1.5708 -1.3243 1.5851" />
    <parent
      link="base_link" />
    <child
      link="front_left_wheel" />
    <axis
      xyz="0 0 0" />
  </joint>
  <link
    name="front_right_wheel">
    <inertial>
      <origin
        xyz="-2.3483E-12 -2.8497E-13 0.014176"
        rpy="0 0 0" />
      <mass
        value="0.093783" />
      <inertia
        ixx="3.0978E-05"
        ixy="-3.4152E-09"
        ixz="-6.7962E-15"
        iyy="3.1005E-05"
        iyz="-8.2473E-16"
        izz="4.7784E-05" />
    </inertial>
    <visual>
      <origin
        xyz="0 0 0"
        rpy="0 0 0" />
      <geometry>
        <mesh
          filename="package://pick_ball_mbot/meshes/front_right_wheel.STL" />
      </geometry>
      <material
        name="">
        <color
          rgba="1 1 1 1" />
      </material>
    </visual>
    <collision>
      <origin
        xyz="0 0 0"
        rpy="0 0 0" />
      <geometry>
        <mesh
          filename="package://pick_ball_mbot/meshes/front_right_wheel.STL" />
      </geometry>
    </collision>
  </link>
  <joint
    name="front_right_wheel_joint"
    type="continuous">
    <origin
      xyz="0.14255 -0.17412 0.032"
      rpy="-1.5708 1.45 -1.5827" />
    <parent
      link="base_link" />
    <child
      link="front_right_wheel" />
    <axis
      xyz="0 0 0" />
  </joint>
  <link
    name="rear_right_wheel">
    <inertial>
      <origin
        xyz="-1.49956436157339E-13 3.20965476419133E-12 0.0148235876551461"
        rpy="0 0 0" />
      <mass
        value="0.0937829390237726" />
      <inertia
        ixx="3.10054780216612E-05"
        ixy="1.32435143883117E-09"
        ixz="2.9614191177372E-16"
        iyy="3.09771986932004E-05"
        iyz="-6.33701481449748E-15"
        izz="4.77838078287252E-05" />
    </inertial>
    <visual>
      <origin
        xyz="0 0 0"
        rpy="0 0 0" />
      <geometry>
        <mesh
          filename="package://pick_ball_mbot/meshes/rear_right_wheel.STL" />
      </geometry>
      <material
        name="">
        <color
          rgba="1 1 1 1" />
      </material>
    </visual>
    <collision>
      <origin
        xyz="0 0 0"
        rpy="0 0 0" />
      <geometry>
        <mesh
          filename="package://pick_ball_mbot/meshes/rear_right_wheel.STL" />
      </geometry>
    </collision>
  </link>
  <joint
    name="rear_right_wheel_joint"
    type="continuous">
    <origin
      xyz="0.1716 -0.03209 0.032"
      rpy="-1.5708 -0.046695 1.5685" />
    <parent
      link="base_link" />
    <child
      link="rear_right_wheel" />
    <axis
      xyz="0 0 0" />
  </joint>
  <link
    name="rear_left_wheel">
    <inertial>
      <origin
        xyz="3.21307563888595E-12 -1.42802436542411E-14 0.0141764123448602"
        rpy="0 0 0" />
      <mass
        value="0.0937829390237727" />
      <inertia
        ixx="3.09771374888205E-05"
        ixy="1.39076431308829E-10"
        ixz="6.3436675045065E-15"
        iyy="3.10055392260229E-05"
        iyz="-2.99974052448107E-17"
        izz="4.77838078287253E-05" />
    </inertial>
    <visual>
      <origin
        xyz="0 0 0"
        rpy="0 0 0" />
      <geometry>
        <mesh
          filename="package://pick_ball_mbot/meshes/rear_left_wheel.STL" />
      </geometry>
      <material
        name="">
        <color
          rgba="1 1 1 1" />
      </material>
    </visual>
    <collision>
      <origin
        xyz="0 0 0"
        rpy="0 0 0" />
      <geometry>
        <mesh
          filename="package://pick_ball_mbot/meshes/rear_left_wheel.STL" />
      </geometry>
    </collision>
  </link>
  <joint
    name="rear_left_wheel_joint"
    type="continuous">
    <origin
      xyz="-0.015598 -0.03204 0.032"
      rpy="-1.5708 -1.5659 1.5749" />
    <parent
      link="base_link" />
    <child
      link="rear_left_wheel" />
    <axis
      xyz="0 0 0" />
  </joint>
  <link
    name="collector">
    <inertial>
      <origin
        xyz="0.0029090749419864 -0.0408902154506417 0.17346881906326"
        rpy="0 0 0" />
      <mass
        value="0.373810739586052" />
      <inertia
        ixx="0.00346608745595317"
        ixy="9.69850646062496E-06"
        ixz="-2.84961455725415E-05"
        iyy="0.00429300102970144"
        iyz="0.00059927618147211"
        izz="0.00198702344544181" />
    </inertial>
    <visual>
      <origin
        xyz="0 0 0"
        rpy="0 0 0" />
      <geometry>
        <mesh
          filename="package://pick_ball_mbot/meshes/collector.STL" />
      </geometry>
      <material
        name="">
        <color
          rgba="1 1 1 1" />
      </material>
    </visual>
    <collision>
      <origin
        xyz="0 0 0"
        rpy="0 0 0" />
      <geometry>
        <mesh
          filename="package://pick_ball_mbot/meshes/collector.STL" />
      </geometry>
    </collision>
  </link>
  <joint
    name="collector_joint"
    type="fixed">
    <origin
      xyz="0.0670003971540816 -0.162246633313628 0.110166666666642"
      rpy="1.5707963267957 0 -3.14159265358971" />
    <parent
      link="base_link" />
    <child
      link="collector" />
    <axis
      xyz="0 0 0" />
  </joint>
  <link
    name="left_cover">
    <inertial>
      <origin
        xyz="0.035432 0.17477 0.10116"
        rpy="0 0 0" />
      <mass
        value="0.35719" />
      <inertia
        ixx="0.0023208"
        ixy="-0.00015274"
        ixz="-8.1174E-05"
        iyy="0.0020745"
        iyz="-0.00030739"
        izz="0.0010449" />
    </inertial>
    <visual>
      <origin
        xyz="0 0 0"
        rpy="0 0 0" />
      <geometry>
        <mesh
          filename="package://pick_ball_mbot/meshes/left_cover.STL" />
      </geometry>
      <material
        name="">
        <color
          rgba="1 1 1 1" />
      </material>
    </visual>
    <collision>
      <origin
        xyz="0 0 0"
        rpy="0 0 0" />
      <geometry>
        <mesh
          filename="package://pick_ball_mbot/meshes/left_cover.STL" />
      </geometry>
    </collision>
  </link>
  <joint
    name="left_cover_joint"
    type="fixed">
    <origin
      xyz="0.0101401985770408 -0.110166666666584 0.0722458562709188"
      rpy="-1.5707963267957 0 0" />
    <parent
      link="collector" />
    <child
      link="left_cover" />
    <axis
      xyz="0 0 0" />
  </joint>
  <link
    name="kinect">
    <inertial>
      <origin
        xyz="-9.9558E-05 2.7756E-17 0.0098148"
        rpy="0 0 0" />
      <mass
        value="0.040237" />
      <inertia
        ixx="2.386E-06"
        ixy="-1.019E-20"
        ixz="3.6524E-08"
        iyy="4.5536E-05"
        iyz="2.8142E-22"
        izz="4.532E-05" />
    </inertial>
    <visual>
      <origin
        xyz="0 0 0"
        rpy="0 0 0" />
      <geometry>
        <mesh
          filename="package://pick_ball_mbot/meshes/kinect.STL" />
      </geometry>
      <material
        name="">
        <color
          rgba="1 1 1 1" />
      </material>
    </visual>
    <collision>
      <origin
        xyz="0 0 0"
        rpy="0 0 0" />
      <geometry>
        <mesh
          filename="package://pick_ball_mbot/meshes/kinect.STL" />
      </geometry>
    </collision>
  </link>
  <joint
    name="kinect_joint"
    type="fixed">
    <origin
      xyz="-0.00214019857701338 0.224918130169899 0.250000005060766"
      rpy="1.57079028822492 0 3.14159265358978" />
    <parent
      link="left_cover" />
    <child
      link="kinect" />
    <axis
      xyz="0 0 0" />
  </joint>
  <link
    name="laser">
    <inertial>
      <origin
        xyz="5.5511E-17 0.018987 5.5511E-17"
        rpy="0 0 0" />
      <mass
        value="0.10603" />
      <inertia
        ixx="3.6368E-05"
        ixy="1.7858E-21"
        ixz="5.481E-35"
        iyy="4.7093E-05"
        iyz="-1.7328E-20"
        izz="3.6368E-05" />
    </inertial>
    <visual>
      <origin
        xyz="0 0 0"
        rpy="0 0 0" />
      <geometry>
        <mesh
          filename="package://pick_ball_mbot/meshes/laser.STL" />
      </geometry>
      <material
        name="">
        <color
          rgba="0.6549 0 0.14902 1" />
      </material>
    </visual>
    <collision>
      <origin
        xyz="0 0 0"
        rpy="0 0 0" />
      <geometry>
        <mesh
          filename="package://pick_ball_mbot/meshes/laser.STL" />
      </geometry>
    </collision>
  </link>
  <joint
    name="laser_joint"
    type="fixed">
    <origin
      xyz="0 0.00900000000000001 0.0100000000000002"
      rpy="3.14159265358979 0 3.14159265358979" />
    <parent
      link="kinect" />
    <child
      link="laser" />
    <axis
      xyz="0 0 0" />
  </joint>
  <link
    name="paddle">
    <inertial>
      <origin
        xyz="0.0097338 -1.7902E-14 -7.9264E-13"
        rpy="0 0 0" />
      <mass
        value="0.16555" />
      <inertia
        ixx="0.00063183"
        ixy="3.4087E-17"
        ixz="-5.3664E-15"
        iyy="0.00050637"
        iyz="1.4736E-13"
        izz="0.00050637" />
    </inertial>
    <visual>
      <origin
        xyz="0 0 0"
        rpy="0 0 0" />
      <geometry>
        <mesh
          filename="package://pick_ball_mbot/meshes/paddle.STL" />
      </geometry>
      <material
        name="">
        <color
          rgba="1 1 1 1" />
      </material>
    </visual>
    <collision>
      <origin
        xyz="0 0 0"
        rpy="0 0 0" />
      <geometry>
        <mesh
          filename="package://pick_ball_mbot/meshes/paddle.STL" />
      </geometry>
    </collision>
  </link>
  <joint
    name="paddle_joint"
    type="continuous">
    <origin
      xyz="0 0.22408 0.12"
      rpy="0.94075 0 3.1416" />
    <parent
      link="left_cover" />
    <child
      link="paddle" />
    <axis
      xyz="1 0 0" />
  </joint>
  <link
    name="right_cover">
    <inertial>
      <origin
        xyz="-0.011894 -0.037433 0.0055616"
        rpy="0 0 0" />
      <mass
        value="0.11834" />
      <inertia
        ixx="0.00023044"
        ixy="-3.8219E-06"
        ixz="2.9166E-05"
        iyy="0.00047003"
        iyz="-3.578E-05"
        izz="0.00064825" />
    </inertial>
    <visual>
      <origin
        xyz="0 0 0"
        rpy="0 0 0" />
      <geometry>
        <mesh
          filename="package://pick_ball_mbot/meshes/right_cover.STL" />
      </geometry>
      <material
        name="">
        <color
          rgba="1 1 1 1" />
      </material>
    </visual>
    <collision>
      <origin
        xyz="0 0 0"
        rpy="0 0 0" />
      <geometry>
        <mesh
          filename="package://pick_ball_mbot/meshes/right_cover.STL" />
      </geometry>
    </collision>
  </link>
  <joint
    name="right_cover_joint"
    type="fixed">
    <origin
      xyz="-0.055 0.0098333 -0.15183"
      rpy="-1.5708 0 1.5708" />
    <parent
      link="collector" />
    <child
      link="right_cover" />
    <axis
      xyz="0 0 0" />
  </joint>
  <link
    name="support_rod">
    <inertial>
      <origin
        xyz="0.031945 0.03855 0"
        rpy="0 0 0" />
      <mass
        value="0.010225" />
      <inertia
        ixx="9.1281E-06"
        ixy="6.7006E-19"
        ixz="-2.026E-19"
        iyy="1.1576E-05"
        iyz="-1.0918E-21"
        izz="2.0462E-05" />
    </inertial>
    <visual>
      <origin
        xyz="0 0 0"
        rpy="0 0 0" />
      <geometry>
        <mesh
          filename="package://pick_ball_mbot/meshes/support_rod.STL" />
      </geometry>
      <material
        name="">
        <color
          rgba="1 1 1 1" />
      </material>
    </visual>
    <collision>
      <origin
        xyz="0 0 0"
        rpy="0 0 0" />
      <geometry>
        <mesh
          filename="package://pick_ball_mbot/meshes/support_rod.STL" />
      </geometry>
    </collision>
  </link>
  <joint
    name="support_rod_joint"
    type="fixed">
    <origin
      xyz="0.095433 -0.16212 0.015"
      rpy="1.5708 0 -3.1416" />
    <parent
      link="base_link" />
    <child
      link="support_rod" />
    <axis
      xyz="0 0 0" />
  </joint>
</robot>